Workbook

Sheet Overview
A2: ATLAS data for OpenPath
A4: Useful starter data for your map and route prototype.
A5: Verify the pilot buildings, entrances, and connecting paths before offering accessibility routes.
A7: Inventory | B7: Count | C7: Meaning
A8: Landmarks | B8: =_xlfn.COUNTIFS('Locations'!C6:C455,"landmark") -> 73 | C8: Building and place labels. These are not documented entrance locations.
A9: Path points | B9: =_xlfn.COUNTIFS('Locations'!C6:C455,"path_point") -> 377 | C9: Intermediate points used to connect routes.
A10: Connections | B10: =COUNTA('Connections'!A6:A589) -> 584 | C10: Connections treated as bidirectional in the ATLAS app.
A11: Legacy TRUE labels | B11: =_xlfn.COUNTIFS('Connections'!D6:D589,"TRUE") -> 570 | C11: The source calls these accessible. Current conditions are unverified.
A12: Legacy FALSE labels | B12: =_xlfn.COUNTIFS('Connections'!D6:D589,"FALSE") -> 14 | C12: The source calls these inaccessible. The reason is not recorded.
A13: Field-checked connections | B13: =_xlfn.COUNTIFS('Connections'!F6:F589,"checked") -> 0 | C13: Manual status in Connections. Checked does not itself mean accessible.
A14: Confirmed accessible | B14: =_xlfn.COUNTIFS('Connections'!G6:G589,"yes") -> 0 | C14: The new field starts unknown for every connection.
A16: Next steps for your team
A18: Role | B18: Step | C18: Action
A19: Data team | B19: 1 | C19: Start with your two or three pilot buildings and one connecting outdoor route. Verify the actual entrances.
A20: Data team | B20: 2 | C20: Walk each pilot segment. Record stairs, ramps, surface, width, slope, access restrictions, date, and evidence.
A21: Backend | B21: 3 | C21: Import Locations and Connections by ID. Keep the legacy flag separate from confirmed accessibility.
A22: Pathfinder | B22: 4 | C22: Use the coordinates for prototype distances. Return “no verified route available” when the verified graph cannot connect the request.
A23: Frontend | B23: 5 | C23: Plot the points and connections in Leaflet. Label unverified data and preserve GPS accuracy information.
A25: How the file is organized
A27: Locations | C27: All 448 points in one ID-based table. Landmarks are alphabetized and path points are sorted by number.
A28: Connections | C28: All 584 edges. One obvious spelling mismatch is mapped to the existing landmark ID and logged.
A29: Issues | C29: Exact source rows, unresolved problems, code review notes, and long segments to inspect.
A30: Landmarks / Nodes / Edges | C30: Original source records and values, with the original row numbers retained.
A32: Before marking a connection checked
A34: Fill the applicable observations, verifier, date, and evidence. Set confirmed_accessible separately.
A35: Unknown is never equivalent to accessible. A legacy FALSE label does not prove that the segment has stairs.
A37: Implementation notes
A39: Distance units | C39: straight_line_m uses Haversine distance with Earth radius 6,371,000 m. It is not a surveyed path length.
A40: IDs | C40: Do not regenerate L IDs after sorting. Keep an explicit location-to-entrance mapping as entrances are verified.
A41: App compatibility | C41: The existing app is Kotlin/Android. Its CSV data transfers to your web project. The Android UI needs a web implementation.

Sheet Locations
A2: Locations
A4: L001–L071 are assigned landmark IDs. Existing N IDs are kept. IDs stay fixed when sorted.
A5: node_id | B5: label | C5: kind | D5: latitude | E5: longitude | F5: edge_count | G5: legacy_true_count | H5: confirmed_entrance | I5: field_status | J5: verified_on | K5: verified_by | L5: notes | M5: source_sheet | N5: source_row
A6: L069 | B6: 86 Field | C6: landmark | D6: 42.730353 | E6: -73.67995 | F6: =_xlfn.COUNTIFS('Connections'!$B$6:$B$589,A6)+_xlfn.COUNTIFS('Connections'!$C$6:$C$589,A6) -> 1 | G6: =_xlfn.COUNTIFS('Connections'!$B$6:$B$589,A6,'Connections'!$D$6:$D$589,"TRUE")+_xlfn.COUNTIFS('Connections'!$C$6:$C$589,A6,'Connections'!$D$6:$D$589,"TRUE") -> 1 | H6: unknown | I6: unverified | M6: Landmarks | N6: 70
A7: L013 | B7: 87 Gymnasium | C7: landmark | D7: 42.730785 | E7: -73.678864 | F7: =_xlfn.COUNTIFS('Connections'!$B$6:$B$589,A7)+_xlfn.COUNTIFS('Connections'!$C$6:$C$589,A7) -> 1 | G7: =_xlfn.COUNTIFS('Connections'!$B$6:$B$589,A7,'Connections'!$D$6:$D$589,"TRUE")+_xlfn.COUNTIFS('Connections'!$C$6:$C$589,A7,'Connections'!$D$6:$D$589,"TRUE") -> 1 | H7: unknown | I7: unverified | M7: Landmarks | N7: 14
A8: L058 | B8: Academy Hall | C8: landmark | D8: 42.72745 | E8: -73.678651 | F8: =_xlfn.COUNTIFS('Connections'!$B$6:$B$589,A8)+_xlfn.COUNTIFS('Connections'!$C$6:$C$589,A8) -> 1 | G8: =_xlfn.COUNTIFS('Connections'!$B$6:$B$589,A8,'Connections'!$D$6:$D$589,"TRUE")+_xlfn.COUNTIFS('Connections'!$C$6:$C$589,A8,'Connections'!$D$6:$D$589,"TRUE") -> 1 | H8: unknown | I8: unverified | M8: Landmarks | N8: 59
A9: L033 | B9: Admissions Office | C9: landmark | D9: 42.730656 | E9: -73.675538 | F9: =_xlfn.COUNTIFS('Connections'!$B$6:$B$589,A9)+_xlfn.COUNTIFS('Connections'!$C$6:$C$589,A9) -> 1 | G9: =_xlfn.COUNTIFS('Connections'!$B$6:$B$589,A9,'Connections'!$D$6:$D$589,"TRUE")+_xlfn.COUNTIFS('Connections'!$C$6:$C$589,A9,'Connections'!$D$6:$D$589,"TRUE") -> 1 | H9: unknown | I9: unverified | M9: Landmarks | N9: 34
A10: L035 | B10: Alumni Sports and Recreation Center (Armory) | C10: landmark | D10: 42.728465 | E10: -73.676973 | F10: =_xlfn.COUNTIFS('Connections'!$B$6:$B$589,A10)+_xlfn.COUNTIFS('Connections'!$C$6:$C$589,A10) -> 2 | G10: =_xlfn.COUNTIFS('Connections'!$B$6:$B$589,A10,'Connections'!$D$6:$D$589,"TRUE")+_xlfn.COUNTIFS('Connections'!$C$6:$C$589,A10,'Connections'!$D$6:$D$589,"TRUE") -> 2 | H10: unknown | I10: unverified | M10: Landmarks | N10: 36
A11: L026 | B11: Amos Eaton Hall | C11: landmark | D11: 42.730144 | E11: -73.682291 | F11: =_xlfn.COUNTIFS('Connections'!$B$6:$B$589,A11)+_xlfn.COUNTIFS('Connections'!$C$6:$C$589,A11) -> 3 | G11: =_xlfn.COUNTIFS('Connections'!$B$6:$B$589,A11,'Connections'!$D$6:$D$589,"TRUE")+_xlfn.COUNTIFS('Connections'!$C$6:$C$589,A11,'Connections'!$D$6:$D$589,"TRUE") -> 3 | H11: unknown | I11: unverified | M11: Landmarks | N11: 27
A12: L060 | B12: Barton Hall | C12: landmark | D12: 42.729087 | E12: -73.67409 | F12: =_xlfn.COUNTIFS('Connections'!$B$6:$B$589,A12)+_xlfn.COUNTIFS('Connections'!$C$6:$C$589,A12) -> 1 | G12: =_xlfn.COUNTIFS('Connections'!$B$6:$B$589,A12,'Connections'!$D$6:$D$589,"TRUE")+_xlfn.COUNTIFS('Connections'!$C$6:$C$589,A12,'Connections'!$D$6:$D$589,"TRUE") -> 1 | H12: unknown | I12: unverified | M12: Landmarks | N12: 61
A13: L027 | B13: Black Cultural Center | C13: landmark | D13: 42.732485 | E13: -73.682878 | F13: =_xlfn.COUNTIFS('Connections'!$B$6:$B$589,A13)+_xlfn.COUNTIFS('Connections'!$C$6:$C$589,A13) -> 1 | G13: =_xlfn.COUNTIFS('Connections'!$B$6:$B$589,A13,'Connections'!$D$6:$D$589,"TRUE")+_xlfn.COUNTIFS('Connections'!$C$6:$C$589,A13,'Connections'!$D$6:$D$589,"TRUE") -> 1 | H13: unknown | I13: unverified | M13: Landmarks | N13: 28
A14: L029 | B14: Blaw-Knox 1&2 | C14: landmark | D14: 42.732152 | E14: -73.680856 | F14: =_xlfn.COUNTIFS('Connections'!$B$6:$B$589,A14)+_xlfn.COUNTIFS('Connections'!$C$6:$C$589,A14) -> 1 | G14: =_xlfn.COUNTIFS('Connections'!$B$6:$B$589,A14,'Connections'!$D$6:$D$589,"TRUE")+_xlfn.COUNTIFS('Connections'!$C$6:$C$589,A14,'Connections'!$D$6:$D$589,"TRUE") -> 1 | H14: unknown | I14: unverified | M14: Landmarks | N14: 30
A15: L070 | B15: Blitman Commons | C15: landmark | D15: 42.731351 | E15: -73.68587 | F15: =_xlfn.COUNTIFS('Connections'!$B$6:$B$589,A15)+_xlfn.COUNTIFS('Connections'!$C$6:$C$589,A15) -> 1 | G15: =_xlfn.COUNTIFS('Connections'!$B$6:$B$589,A15,'Connections'!$D$6:$D$589,"TRUE")+_xlfn.COUNTIFS('Connections'!$C$6:$C$589,A15,'Connections'!$D$6:$D$589,"TRUE") -> 1 | H15: unknown | I15: unverified | M15: Landmarks | N15: 71
A16: L007 | B16: Boiler House | C16: landmark | D16: 42.731225 | E16: -73.681762 | F16: =_xlfn.COUNTIFS('Connections'!$B$6:$B$589,A16)+_xlfn.COUNTIFS('Connections'!$C$6:$C$589,A16) -> 1 | G16: =_xlfn.COUNTIFS('Connections'!$B$6:$B$589,A16,'Connections'!$D$6:$D$589,"TRUE")+_xlfn.COUNTIFS('Connections'!$C$6:$C$589,A16,'Connections'!$D$6:$D$589,"TRUE") -> 1 | H16: unknown | I16: unverified | M16: Landmarks | N16: 8
A17: L064 | B17: Boiler House 2 | C17: landmark | D17: 42.732661 | E17: -73.680222 | F17: =_xlfn.COUNTIFS('Connections'!$B$6:$B$589,A17)+_xlfn.COUNTIFS('Connections'!$C$6:$C$589,A17) -> 2 | G17: =_xlfn.COUNTIFS('Connections'!$B$6:$B$589,A17,'Connections'!$D$6:$D$589,"TRUE")+_xlfn.COUNTIFS('Connections'!$C$6:$C$589,A17,'Connections'!$D$6:$D$589,"TRUE") -> 2 | H17: unknown | I17: unverified | M17: Landmarks | N17: 65
... A65: L008 | B65: Russell Sage Laboratory | C65: landmark | D65: 42.730776 | E65: -73.681689 | F65: =_xlfn.COUNTIFS('Connections'!$B$6:$B$589,A65)+_xlfn.COUNTIFS('Connections'!$C$6:$C$589,A65) -> 1 | G65: =_xlfn.COUNTIFS('Connections'!$B$6:$B$589,A65,'Connections'!$D$6:$D$589,"TRUE")+_xlfn.COUNTIFS('Connections'!$C$6:$C$589,A65,'Connections'!$D$6:$D$589,"TRUE") -> 1 | H65: unknown | I65: unverified | M65: Landmarks | N65: 9
B66: Russell Sage Laboratory (Accessibility Entrance) | C66: landmark | D66: 42.730967 | E66: -73.681176
A67: L068 | B67: Samaritan Hospital | C67: landmark | D67: 42.733245 | E67: -73.672438 | F67: =_xlfn.COUNTIFS('Connections'!$B$6:$B$589,A67)+_xlfn.COUNTIFS('Connections'!$C$6:$C$589,A67) -> 1 | G67: =_xlfn.COUNTIFS('Connections'!$B$6:$B$589,A67,'Connections'!$D$6:$D$589,"TRUE")+_xlfn.COUNTIFS('Connections'!$C$6:$C$589,A67,'Connections'!$D$6:$D$589,"TRUE") -> 1 | H67: unknown | I67: unverified | M67: Landmarks | N67: 69
A68: L028 | B68: Service Building | C68: landmark | D68: 42.732889 | E68: -73.680838 | F68: =_xlfn.COUNTIFS('Connections'!$B$6:$B$589,A68)+_xlfn.COUNTIFS('Connections'!$C$6:$C$589,A68) -> 1 | G68: =_xlfn.COUNTIFS('Connections'!$B$6:$B$589,A68,'Connections'!$D$6:$D$589,"TRUE")+_xlfn.COUNTIFS('Connections'!$C$6:$C$589,A68,'Connections'!$D$6:$D$589,"TRUE") -> 1 | H68: unknown | I68: unverified | M68: Landmarks | N68: 29
A69: L042 | B69: Sharp Hall | C69: landmark | D69: 42.727025 | E69: -73.674648 | F69: =_xlfn.COUNTIFS('Connections'!$B$6:$B$589,A69)+_xlfn.COUNTIFS('Connections'!$C$6:$C$589,A69) -> 2 | G69: =_xlfn.COUNTIFS('Connections'!$B$6:$B$589,A69,'Connections'!$D$6:$D$589,"TRUE")+_xlfn.COUNTIFS('Connections'!$C$6:$C$589,A69,'Connections'!$D$6:$D$589,"TRUE") -> 2 | H69: unknown | I69: unverified | M69: Landmarks | N69: 43
A70: L053 | B70: Stacwyck Apartments | C70: landmark | D70: 42.733731 | E70: -73.664908 | F70: =_xlfn.COUNTIFS('Connections'!$B$6:$B$589,A70)+_xlfn.COUNTIFS('Connections'!$C$6:$C$589,A70) -> 2 | G70: =_xlfn.COUNTIFS('Connections'!$B$6:$B$589,A70,'Connections'!$D$6:$D$589,"TRUE")+_xlfn.COUNTIFS('Connections'!$C$6:$C$589,A70,'Connections'!$D$6:$D$589,"TRUE") -> 2 | H70: unknown | I70: unverified | M70: Landmarks | N70: 54
A71: L066 | B71: Stadium Field | C71: landmark | D71: 42.733044 | E71: -73.666946 | F71: =_xlfn.COUNTIFS('Connections'!$B$6:$B$589,A71)+_xlfn.COUNTIFS('Connections'!$C$6:$C$589,A71) -> 4 | G71: =_xlfn.COUNTIFS('Connections'!$B$6:$B$589,A71,'Connections'!$D$6:$D$589,"TRUE")+_xlfn.COUNTIFS('Connections'!$C$6:$C$589,A71,'Connections'!$D$6:$D$589,"TRUE") -> 4 | H71: unknown | I71: unverified | M71: Landmarks | N71: 67
A72: L009 | B72: Troy Building | C72: landmark | D72: 42.731083 | E72: -73.680523 | F72: =_xlfn.COUNTIFS('Connections'!$B$6:$B$589,A72)+_xlfn.COUNTIFS('Connections'!$C$6:$C$589,A72) -> 1 | G72: =_xlfn.COUNTIFS('Connections'!$B$6:$B$589,A72,'Connections'!$D$6:$D$589,"TRUE")+_xlfn.COUNTIFS('Connections'!$C$6:$C$589,A72,'Connections'!$D$6:$D$589,"TRUE") -> 1 | H72: unknown | I72: unverified | M72: Landmarks | N72: 10
A73: L022 | B73: Voorhees Computing Center | C73: landmark | D73: 42.729247 | E73: -73.681925 | F73: =_xlfn.COUNTIFS('Connections'!$B$6:$B$589,A73)+_xlfn.COUNTIFS('Connections'!$C$6:$C$589,A73) -> 2 | G73: =_xlfn.COUNTIFS('Connections'!$B$6:$B$589,A73,'Connections'!$D$6:$D$589,"TRUE")+_xlfn.COUNTIFS('Connections'!$C$6:$C$589,A73,'Connections'!$D$6:$D$589,"TRUE") -> 2 | H73: unknown | I73: unverified | M73: Landmarks | N73: 23
A74: L006 | B74: Walker Laboratory (South Entrance) | C74: landmark | D74: 42.730689 | E74: -73.682727 | F74: =_xlfn.COUNTIFS('Connections'!$B$6:$B$589,A74)+_xlfn.COUNTIFS('Connections'!$C$6:$C$589,A74) -> 1 | G74: =_xlfn.COUNTIFS('Connections'!$B$6:$B$589,A74,'Connections'!$D$6:$D$589,"TRUE")+_xlfn.COUNTIFS('Connections'!$C$6:$C$589,A74,'Connections'!$D$6:$D$589,"TRUE") -> 1 | H74: unknown | I74: unverified | M74: Landmarks | N74: 7
B75: Walker Laboratory (East Entrance) | C75: landmark | D75: 42.730856 | E75: -73.682293
A76: L044 | B76: Warren Hall | C76: landmark | D76: 42.727913 | E76: -73.675266 | F76: =_xlfn.COUNTIFS('Connections'!$B$6:$B$589,A76)+_xlfn.COUNTIFS('Connections'!$C$6:$C$589,A76) -> 1 | G76: =_xlfn.COUNTIFS('Connections'!$B$6:$B$589,A76,'Connections'!$D$6:$D$589,"TRUE")+_xlfn.COUNTIFS('Connections'!$C$6:$C$589,A76,'Connections'!$D$6:$D$589,"TRUE") -> 1 | H76: unknown | I76: unverified | M76: Landmarks | N76: 45
A77: L004 | B77: West Hall | C77: landmark | D77: 42.731704 | E77: -73.683117 | F77: =_xlfn.COUNTIFS('Connections'!$B$6:$B$589,A77)+_xlfn.COUNTIFS('Connections'!$C$6:$C$589,A77) -> 1 | G77: =_xlfn.COUNTIFS('Connections'!$B$6:$B$589,A77,'Connections'!$D$6:$D$589,"TRUE")+_xlfn.COUNTIFS('Connections'!$C$6:$C$589,A77,'Connections'!$D$6:$D$589,"TRUE") -> 1 | H77: unknown | I77: unverified | M77: Landmarks | N77: 5
A78: L071 | B78: Winslow Building | C78: landmark | D78: 42.730921 | E78: -73.684312 | F78: =_xlfn.COUNTIFS('Connections'!$B$6:$B$589,A78)+_xlfn.COUNTIFS('Connections'!$C$6:$C$589,A78) -> 0 | G78: =_xlfn.COUNTIFS('Connections'!$B$6:$B$589,A78,'Connections'!$D$6:$D$589,"TRUE")+_xlfn.COUNTIFS('Connections'!$C$6:$C$589,A78,'Connections'!$D$6:$D$589,"TRUE") -> 0 | H78: unknown | I78: unverified | L78: No connection. Coordinates overlap N71. Confirm how to link this landmark. | M78: Landmarks | N78: 72
A79: N71 | B79: N71 | C79: path_point | D79: 42.730921 | E79: -73.684312 | F79: =_xlfn.COUNTIFS('Connections'!$B$6:$B$589,A79)+_xlfn.COUNTIFS('Connections'!$C$6:$C$589,A79) -> 1 | G79: =_xlfn.COUNTIFS('Connections'!$B$6:$B$589,A79,'Connections'!$D$6:$D$589,"TRUE")+_xlfn.COUNTIFS('Connections'!$C$6:$C$589,A79,'Connections'!$D$6:$D$589,"TRUE") -> 1 | H79: unknown | I79: unverified | L79: Coordinates overlap Winslow Building. Confirm whether they identify the same place. | M79: Nodes | N79: 2
A80: N72 | B80: N72 | C80: path_point | D80: 42.732426 | E80: -73.671606 | F80: =_xlfn.COUNTIFS('Connections'!$B$6:$B$589,A80)+_xlfn.COUNTIFS('Connections'!$C$6:$C$589,A80) -> 4 | G80: =_xlfn.COUNTIFS('Connections'!$B$6:$B$589,A80,'Connections'!$D$6:$D$589,"TRUE")+_xlfn.COUNTIFS('Connections'!$C$6:$C$589,A80,'Connections'!$D$6:$D$589,"TRUE") -> 4 | H80: unknown | I80: unverified | M80: Nodes | N80: 3
A81: N73 | B81: N73 | C81: path_point | D81: 42.733058 | E81: -73.67654 | F81: =_xlfn.COUNTIFS('Connections'!$B$6:$B$589,A81)+_xlfn.COUNTIFS('Connections'!$C$6:$C$589,A81) -> 4 | G81: =_xlfn.COUNTIFS('Connections'!$B$6:$B$589,A81,'Connections'!$D$6:$D$589,"TRUE")+_xlfn.COUNTIFS('Connections'!$C$6:$C$589,A81,'Connections'!$D$6:$D$589,"TRUE") -> 4 | H81: unknown | I81: unverified | M81: Nodes | N81: 4
A82: N74 | B82: N74 | C82: path_point | D82: 42.730771 | E82: -73.677224 | F82: =_xlfn.COUNTIFS('Connections'!$B$6:$B$589,A82)+_xlfn.COUNTIFS('Connections'!$C$6:$C$589,A82) -> 4 | G82: =_xlfn.COUNTIFS('Connections'!$B$6:$B$589,A82,'Connections'!$D$6:$D$589,"TRUE")+_xlfn.COUNTIFS('Connections'!$C$6:$C$589,A82,'Connections'!$D$6:$D$589,"TRUE") -> 4 | H82: unknown | I82: unverified | M82: Nodes | N82: 5
A83: N75 | B83: N75 | C83: path_point | D83: 42.730644 | E83: -73.676221 | F83: =_xlfn.COUNTIFS('Connections'!$B$6:$B$589,A83)+_xlfn.COUNTIFS('Connections'!$C$6:$C$589,A83) -> 4 | G83: =_xlfn.COUNTIFS('Connections'!$B$6:$B$589,A83,'Connections'!$D$6:$D$589,"TRUE")+_xlfn.COUNTIFS('Connections'!$C$6:$C$589,A83,'Connections'!$D$6:$D$589,"TRUE") -> 4 | H83: unknown | I83: unverified | M83: Nodes | N83: 6
A84: N76 | B84: N76 | C84: path_point | D84: 42.730943 | E84: -73.675648 | F84: =_xlfn.COUNTIFS('Connections'!$B$6:$B$589,A84)+_xlfn.COUNTIFS('Connections'!$C$6:$C$589,A84) -> 3 | G84: =_xlfn.COUNTIFS('Connections'!$B$6:$B$589,A84,'Connections'!$D$6:$D$589,"TRUE")+_xlfn.COUNTIFS('Connections'!$C$6:$C$589,A84,'Connections'!$D$6:$D$589,"TRUE") -> 3 | H84: unknown | I84: unverified | M84: Nodes | N84: 7
A85: N77 | B85: N77 | C85: path_point | D85: 42.731909 | E85: -73.67463 | F85: =_xlfn.COUNTIFS('Connections'!$B$6:$B$589,A85)+_xlfn.COUNTIFS('Connections'!$C$6:$C$589,A85) -> 3 | G85: =_xlfn.COUNTIFS('Connections'!$B$6:$B$589,A85,'Connections'!$D$6:$D$589,"TRUE")+_xlfn.COUNTIFS('Connections'!$C$6:$C$589,A85,'Connections'!$D$6:$D$589,"TRUE") -> 3 | H85: unknown | I85: unverified | M85: Nodes | N85: 8
A86: N78 | B86: N78 | C86: path_point | D86: 42.732714 | E86: -73.674311 | F86: =_xlfn.COUNTIFS('Connections'!$B$6:$B$589,A86)+_xlfn.COUNTIFS('Connections'!$C$6:$C$589,A86) -> 3 | G86: =_xlfn.COUNTIFS('Connections'!$B$6:$B$589,A86,'Connections'!$D$6:$D$589,"TRUE")+_xlfn.COUNTIFS('Connections'!$C$6:$C$589,A86,'Connections'!$D$6:$D$589,"TRUE") -> 3 | H86: unknown | I86: unverified | M86: Nodes | N86: 9
A87: N79 | B87: N79 | C87: path_point | D87: 42.730915 | E87: -73.673793 | F87: =_xlfn.COUNTIFS('Connections'!$B$6:$B$589,A87)+_xlfn.COUNTIFS('Connections'!$C$6:$C$589,A87) -> 3 | G87: =_xlfn.COUNTIFS('Connections'!$B$6:$B$589,A87,'Connections'!$D$6:$D$589,"TRUE")+_xlfn.COUNTIFS('Connections'!$C$6:$C$589,A87,'Connections'!$D$6:$D$589,"TRUE") -> 3 | H87: unknown | I87: unverified | M87: Nodes | N87: 10
A88: N80 | B88: N80 | C88: path_point | D88: 42.731346 | E88: -73.674296 | F88: =_xlfn.COUNTIFS('Connections'!$B$6:$B$589,A88)+_xlfn.COUNTIFS('Connections'!$C$6:$C$589,A88) -> 2 | G88: =_xlfn.COUNTIFS('Connections'!$B$6:$B$589,A88,'Connections'!$D$6:$D$589,"TRUE")+_xlfn.COUNTIFS('Connections'!$C$6:$C$589,A88,'Connections'!$D$6:$D$589,"TRUE") -> 2 | H88: unknown | I88: unverified | M88: Nodes | N88: 11
A89: N81 | B89: N81 | C89: path_point | D89: 42.731265 | E89: -73.671908 | F89: =_xlfn.COUNTIFS('Connections'!$B$6:$B$589,A89)+_xlfn.COUNTIFS('Connections'!$C$6:$C$589,A89) -> 4 | G89: =_xlfn.COUNTIFS('Connections'!$B$6:$B$589,A89,'Connections'!$D$6:$D$589,"TRUE")+_xlfn.COUNTIFS('Connections'!$C$6:$C$589,A89,'Connections'!$D$6:$D$589,"TRUE") -> 4 | H89: unknown | I89: unverified | M89: Nodes | N89: 12
...

Sheet Connections
A2: Connections
A4: Legacy TRUE/FALSE is the source claim. Field inputs are amber. Distances are endpoint estimates in meters.
A5: edge_id | B5: from_id | C5: to_id | D5: legacy_accessible | E5: straight_line_m | F5: field_status | G5: confirmed_accessible | H5: has_stairs | I5: has_ramp | J5: surface | K5: width_m | L5: slope_pct | M5: access_notes | N5: verified_on | O5: verified_by | P5: evidence | Q5: source_row | R5: import_note | S5: from_lat | T5: from_lon | U5: to_lat | V5: to_lon
A6: E0001 | B6: N77 | C6: N78 | D6: TRUE | E6: =2*6371000*ASIN(SQRT(MIN(1,SIN(RADIANS(U6-S6)/2)^2+COS(RADIANS(S6))*COS(RADIANS(U6))*SIN(RADIANS(V6-T6)/2)^2))) -> 93.175043 | F6: unverified | G6: unknown | H6: unknown | I6: unknown | J6: unknown | Q6: 2 | S6: =INDEX('Locations'!$D$6:$D$455,MATCH(B6,'Locations'!$A$6:$A$455,0)) -> 42.731909 | T6: =INDEX('Locations'!$E$6:$E$455,MATCH(B6,'Locations'!$A$6:$A$455,0)) -> -73.67463 | U6: =INDEX('Locations'!$D$6:$D$455,MATCH(C6,'Locations'!$A$6:$A$455,0)) -> 42.732714 | V6: =INDEX('Locations'!$E$6:$E$455,MATCH(C6,'Locations'!$A$6:$A$455,0)) -> -73.674311
A7: E0002 | B7: N73 | C7: N78 | D7: TRUE | E7: =2*6371000*ASIN(SQRT(MIN(1,SIN(RADIANS(U7-S7)/2)^2+COS(RADIANS(S7))*COS(RADIANS(U7))*SIN(RADIANS(V7-T7)/2)^2))) -> 185.99258 | F7: unverified | G7: unknown | H7: unknown | I7: unknown | J7: unknown | Q7: 3 | S7: =INDEX('Locations'!$D$6:$D$455,MATCH(B7,'Locations'!$A$6:$A$455,0)) -> 42.733058 | T7: =INDEX('Locations'!$E$6:$E$455,MATCH(B7,'Locations'!$A$6:$A$455,0)) -> -73.67654 | U7: =INDEX('Locations'!$D$6:$D$455,MATCH(C7,'Locations'!$A$6:$A$455,0)) -> 42.732714 | V7: =INDEX('Locations'!$E$6:$E$455,MATCH(C7,'Locations'!$A$6:$A$455,0)) -> -73.674311
A8: E0003 | B8: N74 | C8: N73 | D8: TRUE | E8: =2*6371000*ASIN(SQRT(MIN(1,SIN(RADIANS(U8-S8)/2)^2+COS(RADIANS(S8))*COS(RADIANS(U8))*SIN(RADIANS(V8-T8)/2)^2))) -> 260.43185 | F8: unverified | G8: unknown | H8: unknown | I8: unknown | J8: unknown | Q8: 4 | S8: =INDEX('Locations'!$D$6:$D$455,MATCH(B8,'Locations'!$A$6:$A$455,0)) -> 42.730771 | T8: =INDEX('Locations'!$E$6:$E$455,MATCH(B8,'Locations'!$A$6:$A$455,0)) -> -73.677224 | U8: =INDEX('Locations'!$D$6:$D$455,MATCH(C8,'Locations'!$A$6:$A$455,0)) -> 42.733058 | V8: =INDEX('Locations'!$E$6:$E$455,MATCH(C8,'Locations'!$A$6:$A$455,0)) -> -73.67654
A9: E0004 | B9: N74 | C9: N75 | D9: TRUE | E9: =2*6371000*ASIN(SQRT(MIN(1,SIN(RADIANS(U9-S9)/2)^2+COS(RADIANS(S9))*COS(RADIANS(U9))*SIN(RADIANS(V9-T9)/2)^2))) -> 83.099533 | F9: unverified | G9: unknown | H9: unknown | I9: unknown | J9: unknown | Q9: 5 | S9: =INDEX('Locations'!$D$6:$D$455,MATCH(B9,'Locations'!$A$6:$A$455,0)) -> 42.730771 | T9: =INDEX('Locations'!$E$6:$E$455,MATCH(B9,'Locations'!$A$6:$A$455,0)) -> -73.677224 | U9: =INDEX('Locations'!$D$6:$D$455,MATCH(C9,'Locations'!$A$6:$A$455,0)) -> 42.730644 | V9: =INDEX('Locations'!$E$6:$E$455,MATCH(C9,'Locations'!$A$6:$A$455,0)) -> -73.676221
A10: E0005 | B10: N76 | C10: N75 | D10: TRUE | E10: =2*6371000*ASIN(SQRT(MIN(1,SIN(RADIANS(U10-S10)/2)^2+COS(RADIANS(S10))*COS(RADIANS(U10))*SIN(RADIANS(V10-T10)/2)^2))) -> 57.399966 | F10: unverified | G10: unknown | H10: unknown | I10: unknown | J10: unknown | Q10: 6 | S10: =INDEX('Locations'!$D$6:$D$455,MATCH(B10,'Locations'!$A$6:$A$455,0)) -> 42.730943 | T10: =INDEX('Locations'!$E$6:$E$455,MATCH(B10,'Locations'!$A$6:$A$455,0)) -> -73.675648 | U10: =INDEX('Locations'!$D$6:$D$455,MATCH(C10,'Locations'!$A$6:$A$455,0)) -> 42.730644 | V10: =INDEX('Locations'!$E$6:$E$455,MATCH(C10,'Locations'!$A$6:$A$455,0)) -> -73.676221
A11: E0006 | B11: N77 | C11: N80 | D11: TRUE | E11: =2*6371000*ASIN(SQRT(MIN(1,SIN(RADIANS(U11-S11)/2)^2+COS(RADIANS(S11))*COS(RADIANS(U11))*SIN(RADIANS(V11-T11)/2)^2))) -> 68.323041 | F11: unverified | G11: unknown | H11: unknown | I11: unknown | J11: unknown | Q11: 7 | S11: =INDEX('Locations'!$D$6:$D$455,MATCH(B11,'Locations'!$A$6:$A$455,0)) -> 42.731909 | T11: =INDEX('Locations'!$E$6:$E$455,MATCH(B11,'Locations'!$A$6:$A$455,0)) -> -73.67463 | U11: =INDEX('Locations'!$D$6:$D$455,MATCH(C11,'Locations'!$A$6:$A$455,0)) -> 42.731346 | V11: =INDEX('Locations'!$E$6:$E$455,MATCH(C11,'Locations'!$A$6:$A$455,0)) -> -73.674296
A12: E0007 | B12: N79 | C12: N80 | D12: TRUE | E12: =2*6371000*ASIN(SQRT(MIN(1,SIN(RADIANS(U12-S12)/2)^2+COS(RADIANS(S12))*COS(RADIANS(U12))*SIN(RADIANS(V12-T12)/2)^2))) -> 63.127867 | F12: unverified | G12: unknown | H12: unknown | I12: unknown | J12: unknown | Q12: 8 | S12: =INDEX('Locations'!$D$6:$D$455,MATCH(B12,'Locations'!$A$6:$A$455,0)) -> 42.730915 | T12: =INDEX('Locations'!$E$6:$E$455,MATCH(B12,'Locations'!$A$6:$A$455,0)) -> -73.673793 | U12: =INDEX('Locations'!$D$6:$D$455,MATCH(C12,'Locations'!$A$6:$A$455,0)) -> 42.731346 | V12: =INDEX('Locations'!$E$6:$E$455,MATCH(C12,'Locations'!$A$6:$A$455,0)) -> -73.674296
A13: E0008 | B13: N82 | C13: N79 | D13: TRUE | E13: =2*6371000*ASIN(SQRT(MIN(1,SIN(RADIANS(U13-S13)/2)^2+COS(RADIANS(S13))*COS(RADIANS(U13))*SIN(RADIANS(V13-T13)/2)^2))) -> 66.002157 | F13: unverified | G13: unknown | H13: unknown | I13: unknown | J13: unknown | Q13: 9 | S13: =INDEX('Locations'!$D$6:$D$455,MATCH(B13,'Locations'!$A$6:$A$455,0)) -> 42.731127 | T13: =INDEX('Locations'!$E$6:$E$455,MATCH(B13,'Locations'!$A$6:$A$455,0)) -> -73.673038 | U13: =INDEX('Locations'!$D$6:$D$455,MATCH(C13,'Locations'!$A$6:$A$455,0)) -> 42.730915 | V13: =INDEX('Locations'!$E$6:$E$455,MATCH(C13,'Locations'!$A$6:$A$455,0)) -> -73.673793
A14: E0009 | B14: N82 | C14: N81 | D14: TRUE | E14: =2*6371000*ASIN(SQRT(MIN(1,SIN(RADIANS(U14-S14)/2)^2+COS(RADIANS(S14))*COS(RADIANS(U14))*SIN(RADIANS(V14-T14)/2)^2))) -> 93.566653 | F14: unverified | G14: unknown | H14: unknown | I14: unknown | J14: unknown | Q14: 10 | S14: =INDEX('Locations'!$D$6:$D$455,MATCH(B14,'Locations'!$A$6:$A$455,0)) -> 42.731127 | T14: =INDEX('Locations'!$E$6:$E$455,MATCH(B14,'Locations'!$A$6:$A$455,0)) -> -73.673038 | U14: =INDEX('Locations'!$D$6:$D$455,MATCH(C14,'Locations'!$A$6:$A$455,0)) -> 42.731265 | V14: =INDEX('Locations'!$E$6:$E$455,MATCH(C14,'Locations'!$A$6:$A$455,0)) -> -73.671908
A15: E0010 | B15: N72 | C15: N83 | D15: TRUE | E15: =2*6371000*ASIN(SQRT(MIN(1,SIN(RADIANS(U15-S15)/2)^2+COS(RADIANS(S15))*COS(RADIANS(U15))*SIN(RADIANS(V15-T15)/2)^2))) -> 87.557406 | F15: unverified | G15: unknown | H15: unknown | I15: unknown | J15: unknown | Q15: 11 | S15: =INDEX('Locations'!$D$6:$D$455,MATCH(B15,'Locations'!$A$6:$A$455,0)) -> 42.732426 | T15: =INDEX('Locations'!$E$6:$E$455,MATCH(B15,'Locations'!$A$6:$A$455,0)) -> -73.671606 | U15: =INDEX('Locations'!$D$6:$D$455,MATCH(C15,'Locations'!$A$6:$A$455,0)) -> 42.732507 | V15: =INDEX('Locations'!$E$6:$E$455,MATCH(C15,'Locations'!$A$6:$A$455,0)) -> -73.672672
A16: E0011 | B16: N78 | C16: N83 | D16: TRUE | E16: =2*6371000*ASIN(SQRT(MIN(1,SIN(RADIANS(U16-S16)/2)^2+COS(RADIANS(S16))*COS(RADIANS(U16))*SIN(RADIANS(V16-T16)/2)^2))) -> 135.86053 | F16: unverified | G16: unknown | H16: unknown | I16: unknown | J16: unknown | Q16: 12 | S16: =INDEX('Locations'!$D$6:$D$455,MATCH(B16,'Locations'!$A$6:$A$455,0)) -> 42.732714 | T16: =INDEX('Locations'!$E$6:$E$455,MATCH(B16,'Locations'!$A$6:$A$455,0)) -> -73.674311 | U16: =INDEX('Locations'!$D$6:$D$455,MATCH(C16,'Locations'!$A$6:$A$455,0)) -> 42.732507 | V16: =INDEX('Locations'!$E$6:$E$455,MATCH(C16,'Locations'!$A$6:$A$455,0)) -> -73.672672
A17: E0012 | B17: N77 | C17: N84 | D17: TRUE | E17: =2*6371000*ASIN(SQRT(MIN(1,SIN(RADIANS(U17-S17)/2)^2+COS(RADIANS(S17))*COS(RADIANS(U17))*SIN(RADIANS(V17-T17)/2)^2))) -> 71.624454 | F17: unverified | G17: unknown | H17: unknown | I17: unknown | J17: unknown | Q17: 13 | S17: =INDEX('Locations'!$D$6:$D$455,MATCH(B17,'Locations'!$A$6:$A$455,0)) -> 42.731909 | T17: =INDEX('Locations'!$E$6:$E$455,MATCH(B17,'Locations'!$A$6:$A$455,0)) -> -73.67463 | U17: =INDEX('Locations'!$D$6:$D$455,MATCH(C17,'Locations'!$A$6:$A$455,0)) -> 42.731369 | V17: =INDEX('Locations'!$E$6:$E$455,MATCH(C17,'Locations'!$A$6:$A$455,0)) -> -73.675107
... A93: E0088 | B93: N129 | C93: N130 | D93: FALSE | E93: =2*6371000*ASIN(SQRT(MIN(1,SIN(RADIANS(U93-S93)/2)^2+COS(RADIANS(S93))*COS(RADIANS(U93))*SIN(RADIANS(V93-T93)/2)^2))) -> 49.004633 | F93: unverified | G93: unknown | H93: unknown | I93: unknown | J93: unknown | Q93: 89 | S93: =INDEX('Locations'!$D$6:$D$455,MATCH(B93,'Locations'!$A$6:$A$455,0)) -> 42.730012 | T93: =INDEX('Locations'!$E$6:$E$455,MATCH(B93,'Locations'!$A$6:$A$455,0)) -> -73.678513 | U93: =INDEX('Locations'!$D$6:$D$455,MATCH(C93,'Locations'!$A$6:$A$455,0)) -> 42.729575 | V93: =INDEX('Locations'!$E$6:$E$455,MATCH(C93,'Locations'!$A$6:$A$455,0)) -> -73.678593
A94: E0089 | B94: L001 | C94: N130 | D94: TRUE | E94: =2*6371000*ASIN(SQRT(MIN(1,SIN(RADIANS(U94-S94)/2)^2+COS(RADIANS(S94))*COS(RADIANS(U94))*SIN(RADIANS(V94-T94)/2)^2))) -> 39.096005 | F94: unverified | G94: unknown | H94: unknown | I94: unknown | J94: unknown | Q94: 90 | R94: Mapped Russell Sage Dining Hall to Russell Sage Dining Hall (L001). | S94: =INDEX('Locations'!$D$6:$D$455,MATCH(B94,'Locations'!$A$6:$A$455,0)) -> 42.729784 | T94: =INDEX('Locations'!$E$6:$E$455,MATCH(B94,'Locations'!$A$6:$A$455,0)) -> -73.678208 | U94: =INDEX('Locations'!$D$6:$D$455,MATCH(C94,'Locations'!$A$6:$A$455,0)) -> 42.729575 | V94: =INDEX('Locations'!$E$6:$E$455,MATCH(C94,'Locations'!$A$6:$A$455,0)) -> -73.678593
A95: E0090 | B95: N131 | C95: N132 | D95: TRUE | E95: =2*6371000*ASIN(SQRT(MIN(1,SIN(RADIANS(U95-S95)/2)^2+COS(RADIANS(S95))*COS(RADIANS(U95))*SIN(RADIANS(V95-T95)/2)^2))) -> 49.405793 | F95: unverified | G95: unknown | H95: unknown | I95: unknown | J95: unknown | Q95: 91 | S95: =INDEX('Locations'!$D$6:$D$455,MATCH(B95,'Locations'!$A$6:$A$455,0)) -> 42.72938 | T95: =INDEX('Locations'!$E$6:$E$455,MATCH(B95,'Locations'!$A$6:$A$455,0)) -> -73.677972 | U95: =INDEX('Locations'!$D$6:$D$455,MATCH(C95,'Locations'!$A$6:$A$455,0)) -> 42.729295 | V95: =INDEX('Locations'!$E$6:$E$455,MATCH(C95,'Locations'!$A$6:$A$455,0)) -> -73.677379
A96: E0091 | B96: N131 | C96: N133 | D96: FALSE | E96: =2*6371000*ASIN(SQRT(MIN(1,SIN(RADIANS(U96-S96)/2)^2+COS(RADIANS(S96))*COS(RADIANS(U96))*SIN(RADIANS(V96-T96)/2)^2))) -> 47.323598 | F96: unverified | G96: unknown | H96: unknown | I96: unknown | J96: unknown | Q96: 92 | S96: =INDEX('Locations'!$D$6:$D$455,MATCH(B96,'Locations'!$A$6:$A$455,0)) -> 42.72938 | T96: =INDEX('Locations'!$E$6:$E$455,MATCH(B96,'Locations'!$A$6:$A$455,0)) -> -73.677972 | U96: =INDEX('Locations'!$D$6:$D$455,MATCH(C96,'Locations'!$A$6:$A$455,0)) -> 42.729805 | V96: =INDEX('Locations'!$E$6:$E$455,MATCH(C96,'Locations'!$A$6:$A$455,0)) -> -73.677952
A97: E0092 | B97: N127 | C97: N133 | D97: TRUE | E97: =2*6371000*ASIN(SQRT(MIN(1,SIN(RADIANS(U97-S97)/2)^2+COS(RADIANS(S97))*COS(RADIANS(U97))*SIN(RADIANS(V97-T97)/2)^2))) -> 54.210741 | F97: unverified | G97: unknown | H97: unknown | I97: unknown | J97: unknown | Q97: 93 | S97: =INDEX('Locations'!$D$6:$D$455,MATCH(B97,'Locations'!$A$6:$A$455,0)) -> 42.730282 | T97: =INDEX('Locations'!$E$6:$E$455,MATCH(B97,'Locations'!$A$6:$A$455,0)) -> -73.678088 | U97: =INDEX('Locations'!$D$6:$D$455,MATCH(C97,'Locations'!$A$6:$A$455,0)) -> 42.729805 | V97: =INDEX('Locations'!$E$6:$E$455,MATCH(C97,'Locations'!$A$6:$A$455,0)) -> -73.677952
A98: E0093 | B98: N130 | C98: L015 | D98: TRUE | E98: =2*6371000*ASIN(SQRT(MIN(1,SIN(RADIANS(U98-S98)/2)^2+COS(RADIANS(S98))*COS(RADIANS(U98))*SIN(RADIANS(V98-T98)/2)^2))) -> 20.6917 | F98: unverified | G98: unknown | H98: unknown | I98: unknown | J98: unknown | Q98: 94 | S98: =INDEX('Locations'!$D$6:$D$455,MATCH(B98,'Locations'!$A$6:$A$455,0)) -> 42.729575 | T98: =INDEX('Locations'!$E$6:$E$455,MATCH(B98,'Locations'!$A$6:$A$455,0)) -> -73.678593 | U98: =INDEX('Locations'!$D$6:$D$455,MATCH(C98,'Locations'!$A$6:$A$455,0)) -> 42.729403 | V98: =INDEX('Locations'!$E$6:$E$455,MATCH(C98,'Locations'!$A$6:$A$455,0)) -> -73.678687
A99: E0094 | B99: L017 | C99: N134 | D99: TRUE | E99: =2*6371000*ASIN(SQRT(MIN(1,SIN(RADIANS(U99-S99)/2)^2+COS(RADIANS(S99))*COS(RADIANS(U99))*SIN(RADIANS(V99-T99)/2)^2))) -> 15.456242 | F99: unverified | G99: unknown | H99: unknown | I99: unknown | J99: unknown | Q99: 95 | S99: =INDEX('Locations'!$D$6:$D$455,MATCH(B99,'Locations'!$A$6:$A$455,0)) -> 42.729471 | T99: =INDEX('Locations'!$E$6:$E$455,MATCH(B99,'Locations'!$A$6:$A$455,0)) -> -73.679255 | U99: =INDEX('Locations'!$D$6:$D$455,MATCH(C99,'Locations'!$A$6:$A$455,0)) -> 42.72961 | V99: =INDEX('Locations'!$E$6:$E$455,MATCH(C99,'Locations'!$A$6:$A$455,0)) -> -73.679246
A100: E0095 | B100: N130 | C100: N134 | D100: TRUE | E100: =2*6371000*ASIN(SQRT(MIN(1,SIN(RADIANS(U100-S100)/2)^2+COS(RADIANS(S100))*COS(RADIANS(U100))*SIN(RADIANS(V100-T100)/2)^2))) -> 53.439639 | F100: unverified | G100: unknown | H100: unknown | I100: unknown | J100: unknown | Q100: 96 | S100: =INDEX('Locations'!$D$6:$D$455,MATCH(B100,'Locations'!$A$6:$A$455,0)) -> 42.729575 | T100: =INDEX('Locations'!$E$6:$E$455,MATCH(B100,'Locations'!$A$6:$A$455,0)) -> -73.678593 | U100: =INDEX('Locations'!$D$6:$D$455,MATCH(C100,'Locations'!$A$6:$A$455,0)) -> 42.72961 | V100: =INDEX('Locations'!$E$6:$E$455,MATCH(C100,'Locations'!$A$6:$A$455,0)) -> -73.679246
A101: E0096 | B101: N136 | C101: N135 | D101: TRUE | E101: =2*6371000*ASIN(SQRT(MIN(1,SIN(RADIANS(U101-S101)/2)^2+COS(RADIANS(S101))*COS(RADIANS(U101))*SIN(RADIANS(V101-T101)/2)^2))) -> 44.272709 | F101: unverified | G101: unknown | H101: unknown | I101: unknown | J101: unknown | Q101: 97 | S101: =INDEX('Locations'!$D$6:$D$455,MATCH(B101,'Locations'!$A$6:$A$455,0)) -> 42.730667 | T101: =INDEX('Locations'!$E$6:$E$455,MATCH(B101,'Locations'!$A$6:$A$455,0)) -> -73.679381 | U101: =INDEX('Locations'!$D$6:$D$455,MATCH(C101,'Locations'!$A$6:$A$455,0)) -> 42.731058 | V101: =INDEX('Locations'!$E$6:$E$455,MATCH(C101,'Locations'!$A$6:$A$455,0)) -> -73.679277
A102: E0097 | B102: N136 | C102: N137 | D102: TRUE | E102: =2*6371000*ASIN(SQRT(MIN(1,SIN(RADIANS(U102-S102)/2)^2+COS(RADIANS(S102))*COS(RADIANS(U102))*SIN(RADIANS(V102-T102)/2)^2))) -> 54.484377 | F102: unverified | G102: unknown | H102: unknown | I102: unknown | J102: unknown | Q102: 98 | S102: =INDEX('Locations'!$D$6:$D$455,MATCH(B102,'Locations'!$A$6:$A$455,0)) -> 42.730667 | T102: =INDEX('Locations'!$E$6:$E$455,MATCH(B102,'Locations'!$A$6:$A$455,0)) -> -73.679381 | U102: =INDEX('Locations'!$D$6:$D$455,MATCH(C102,'Locations'!$A$6:$A$455,0)) -> 42.730257 | V102: =INDEX('Locations'!$E$6:$E$455,MATCH(C102,'Locations'!$A$6:$A$455,0)) -> -73.679016
A103: E0098 | B103: N138 | C103: N137 | D103: TRUE | E103: =2*6371000*ASIN(SQRT(MIN(1,SIN(RADIANS(U103-S103)/2)^2+COS(RADIANS(S103))*COS(RADIANS(U103))*SIN(RADIANS(V103-T103)/2)^2))) -> 48.361794 | F103: unverified | G103: unknown | H103: unknown | I103: unknown | J103: unknown | Q103: 99 | S103: =INDEX('Locations'!$D$6:$D$455,MATCH(B103,'Locations'!$A$6:$A$455,0)) -> 42.729897 | T103: =INDEX('Locations'!$E$6:$E$455,MATCH(B103,'Locations'!$A$6:$A$455,0)) -> -73.679349 | U103: =INDEX('Locations'!$D$6:$D$455,MATCH(C103,'Locations'!$A$6:$A$455,0)) -> 42.730257 | V103: =INDEX('Locations'!$E$6:$E$455,MATCH(C103,'Locations'!$A$6:$A$455,0)) -> -73.679016
A104: E0099 | B104: N140 | C104: N139 | D104: TRUE | E104: =2*6371000*ASIN(SQRT(MIN(1,SIN(RADIANS(U104-S104)/2)^2+COS(RADIANS(S104))*COS(RADIANS(U104))*SIN(RADIANS(V104-T104)/2)^2))) -> 46.920866 | F104: unverified | G104: unknown | H104: unknown | I104: unknown | J104: unknown | Q104: 100 | S104: =INDEX('Locations'!$D$6:$D$455,MATCH(B104,'Locations'!$A$6:$A$455,0)) -> 42.730365 | T104: =INDEX('Locations'!$E$6:$E$455,MATCH(B104,'Locations'!$A$6:$A$455,0)) -> -73.680869 | U104: =INDEX('Locations'!$D$6:$D$455,MATCH(C104,'Locations'!$A$6:$A$455,0)) -> 42.729989 | V104: =INDEX('Locations'!$E$6:$E$455,MATCH(C104,'Locations'!$A$6:$A$455,0)) -> -73.680608
A105: E0100 | B105: N136 | C105: N143 | D105: TRUE | E105: =2*6371000*ASIN(SQRT(MIN(1,SIN(RADIANS(U105-S105)/2)^2+COS(RADIANS(S105))*COS(RADIANS(U105))*SIN(RADIANS(V105-T105)/2)^2))) -> 36.343547 | F105: unverified | G105: unknown | H105: unknown | I105: unknown | J105: unknown | Q105: 101 | S105: =INDEX('Locations'!$D$6:$D$455,MATCH(B105,'Locations'!$A$6:$A$455,0)) -> 42.730667 | T105: =INDEX('Locations'!$E$6:$E$455,MATCH(B105,'Locations'!$A$6:$A$455,0)) -> -73.679381 | U105: =INDEX('Locations'!$D$6:$D$455,MATCH(C105,'Locations'!$A$6:$A$455,0)) -> 42.730688 | V105: =INDEX('Locations'!$E$6:$E$455,MATCH(C105,'Locations'!$A$6:$A$455,0)) -> -73.679825
A106: E0101 | B106: L069 | C106: N143 | D106: TRUE | E106: =2*6371000*ASIN(SQRT(MIN(1,SIN(RADIANS(U106-S106)/2)^2+COS(RADIANS(S106))*COS(RADIANS(U106))*SIN(RADIANS(V106-T106)/2)^2))) -> 38.653808 | F106: unverified | G106: unknown | H106: unknown | I106: unknown | J106: unknown | Q106: 102 | S106: =INDEX('Locations'!$D$6:$D$455,MATCH(B106,'Locations'!$A$6:$A$455,0)) -> 42.730353 | T106: =INDEX('Locations'!$E$6:$E$455,MATCH(B106,'Locations'!$A$6:$A$455,0)) -> -73.67995 | U106: =INDEX('Locations'!$D$6:$D$455,MATCH(C106,'Locations'!$A$6:$A$455,0)) -> 42.730688 | V106: =INDEX('Locations'!$E$6:$E$455,MATCH(C106,'Locations'!$A$6:$A$455,0)) -> -73.679825
... A589: E0584 | B589: N128 | C589: N448 | D589: TRUE | E589: =2*6371000*ASIN(SQRT(MIN(1,SIN(RADIANS(U589-S589)/2)^2+COS(RADIANS(S589))*COS(RADIANS(U589))*SIN(RADIANS(V589-T589)/2)^2))) -> 26.196167 | F589: unverified | G589: unknown | H589: unknown | I589: unknown | J589: unknown | Q589: 585 | S589: =INDEX('Locations'!$D$6:$D$455,MATCH(B589,'Locations'!$A$6:$A$455,0)) -> 42.730518 | T589: =INDEX('Locations'!$E$6:$E$455,MATCH(B589,'Locations'!$A$6:$A$455,0)) -> -73.678036 | U589: =INDEX('Locations'!$D$6:$D$455,MATCH(C589,'Locations'!$A$6:$A$455,0)) -> 42.730489 | V589: =INDEX('Locations'!$E$6:$E$455,MATCH(C589,'Locations'!$A$6:$A$455,0)) -> -73.677718

Sheet Issues
A2: Issues and reuse notes
A4: Audit dated 2026-09-29. Connectivity assumes bidirectional edges, matching the source app.
A5: Issue ID | B5: Status | C5: Problem | D5: Evidence | E5: Action | F5: Source
A6: I01 | B6: Fixed | C6: Misspelled endpoint | D6: Edges row 90 uses Russell Sage Dining Hall. Landmarks row 2 uses Russell Sage Dining Hall. | E6: Connections maps E0089 to L001. Original data is retained. This repairs a name, not a field observation. | F6: Edges!A90:C90; Landmarks!A2:C2
A7: I02 | B7: Resolve | C7: Winslow has no connection | D7: Winslow Building has degree 0. Its coordinates are within 0.001 m of N71, which is connected. | E7: Confirm the landmark-to-node relationship and entrance on site. No edge or alias has been invented. | F7: Landmarks!A72:C72; Nodes!A2:C2
A8: I03 | B8: Verify | C8: E Complex loses access | D8: Its only source connection is E0194 to N135, flagged FALSE. It is isolated when FALSE edges are excluded. | E8: Verify whether an alternate accessible entrance/path exists. Preserve the FALSE label until checked. | F8: Edges!A195:C195
A9: I04 | B9: Verify | C9: Accessibility has no evidence | D9: All 584 records lack inspection dates, verifier names, and reasons for their TRUE/FALSE labels. | E9: Verify the pilot segments. Leave confirmed_accessible unknown until the team has evidence. | F9: Edges!A1:C585
A10: I05 | B10: Verify | C10: Entrances are unspecified | D10: Landmarks provide only name, latitude, and longitude. No entrance IDs, floors, or door access details are recorded. | E10: Locate the actual usable entrances and connect them to the outdoor graph. Do not assume a building pin is a door. | F10: Landmarks!A1:C72
A11: I06 | B11: Inspect | C11: Long straight segments | D11: 18 source segments exceed 200 m between endpoints. Long segments are inspection candidates, not proven errors. | E11: Check the real path shape, intermediate turns, crossings, and barriers. Add intermediate points if needed. | F11: Long-segment table below
A12: I07 | B12: Reference | C12: Android implementation | D12: Graph.kt reads local CSVs, applies Dijkstra, and treats edges as bidirectional. The UI and location code use Android APIs. | E12: Reuse the data model and algorithm ideas within your chosen web stack. Confirm direction restrictions in the field. | F12: Graph.kt: parseEdgesFromCSV / shortestPath; app/build.gradle.kts
A13: I08 | B13: Handle | C13: No-route result is ambiguous | D13: shortestPath returns an empty Route for an unreachable destination. An empty Route also totals 0 distance. | E13: Return an explicit no-route result. Test disconnected destinations separately from start equals destination. | F13: Graph.kt: shortestPath / Route.totalDistance
A14: I09 | B14: Handle | C14: Nearest-point GPS snapping | D14: getClosestNode selects the geographically nearest node without a maximum-distance or connected-path test. | E14: Keep users within the supported area and use verified, reachable paths. Nearby points can lie across a barrier. | F14: Graph.kt: getClosestNode / startRoute
A15: I10 | B15: Verify | C15: Older source branch | D15: new_main points to a commit dated 2024-12-11. No campus inspection dates are supplied. | E15: Check current campus conditions. The commit date describes the code history, not a field survey. | F15: Repository commit listed below
A16: I11 | B16: Checked | C16: Basic structure is consistent | D16: 448 unique point names. No invalid coordinate ranges, duplicate undirected pairs, or self-loops. One original missing endpoint, fixed in Connections. | E16: Keep import validation for duplicate IDs, unresolved endpoints, and missing coordinates. | F16: All three original source tables
A17: I12 | B17: Snapshot | C17: Graph connectivity | D17: Original: 446 connected points, plus Russell Sage Dining Hall and Winslow isolated. TRUE-only: 445, plus those two and E Complex. | E17: After the spelling fix: 447 connected points (70 landmarks). TRUE-only: 446 (69 landmarks). These are topology checks, not verified routes. | F17: Graph audit on source tables; one documented name fix
A19: Segments over 200 m to inspect
A21: Edge ID | B21: Source row | C21: From | D21: To | E21: Straight line (m) | F21: Review note
A22: E0574 | B22: 575 | C22: N444 | D22: N445 | E22: 414.51834 | F22: Check turns, crossings, and barriers.
A23: E0573 | B23: 574 | C23: N437 | D23: N445 | E23: 407.63552 | F23: Check turns, crossings, and barriers.
A24: E0563 | B24: 564 | C24: N428 | D24: N439 | E24: 298.96342 | F24: Check turns, crossings, and barriers.
A25: E0565 | B25: 566 | C25: N437 | D25: N436 | E25: 296.95166 | F25: Check turns, crossings, and barriers.
A26: E0302 | B26: 303 | C26: N226 | D26: N263 | E26: 262.88041 | F26: Check turns, crossings, and barriers.
A27: E0003 | B27: 4 | C27: N74 | D27: N73 | E27: 260.43185 | F27: Check turns, crossings, and barriers.
A28: E0575 | B28: 576 | C28: N73 | D28: N444 | E28: 250.45967 | F28: Check turns, crossings, and barriers.
A29: E0376 | B29: 377 | C29: N311 | D29: N312 | E29: 250.33488 | F29: Check turns, crossings, and barriers.
A30: E0569 | B30: 570 | C30: N443 | D30: N441 | E30: 250.18359 | F30: Check turns, crossings, and barriers.
A31: E0571 | B31: 572 | C31: N440 | D31: N441 | E31: 245.85403 | F31: Check turns, crossings, and barriers.
A32: E0568 | B32: 569 | C32: N72 | D32: N440 | E32: 243.41309 | F32: Check turns, crossings, and barriers.
A33: E0394 | B33: 395 | C33: N317 | D33: N324 | E33: 233.32242 | F33: Check turns, crossings, and barriers.
... A39: E0566 | B39: 567 | C39: N428 | D39: N436 | E39: 201.67305 | F39: Check turns, crossings, and barriers.
A42: Repository sources
A44: Branch commit | C44: https://github.com/rgtdthrd/RPI-Atlas/commit/ad4c20d72a5a9116513332047e3ffc1b6d84443e
A46: Routing code | C46: https://github.com/rgtdthrd/RPI-Atlas/blob/ad4c20d72a5a9116513332047e3ffc1b6d84443e/app/src/main/java/com/example/myapplication/Graph.kt
A48: Android setup | C48: https://github.com/rgtdthrd/RPI-Atlas/blob/ad4c20d72a5a9116513332047e3ffc1b6d84443e/app/build.gradle.kts
A50: App description | C50: https://github.com/rgtdthrd/RPI-Atlas/blob/ad4c20d72a5a9116513332047e3ffc1b6d84443e/README.md
A52: License | C52: https://github.com/rgtdthrd/RPI-Atlas/blob/ad4c20d72a5a9116513332047e3ffc1b6d84443e/LICENSE
A55: The repository includes an MIT license. Keep its copyright and license notice when copying repository material.
A57: Review method: spreadsheet audit, CSV comparison, and static code inspection. The Android app was not built or run.

Sheet Landmarks
A1: Name | B1: Latitude | C1: Longitude | E1: Original source
A2: Russell Sage Dining Hall | B2: 42.729784 | C2: -73.678208 | E2: ATLAS Graph Data.xlsx / Landmarks
A3: Rensselaer Union | B3: 42.7299 | C3: -73.67667
A4: Pittsburgh Building | B4: 42.73117 | C4: -73.68331 | E4: All original records and values in A:C are preserved.
A5: West Hall | B5: 42.731704 | C5: -73.683117
A6: Carnegie Building | B6: 42.730469 | C6: -73.683207 | E6: Repository comparison
A7: Walker Laboratory | B7: 42.730868 | C7: -73.682524 | E7: All 71 names match in order. Coordinate differences are below 0.001 m.
A8: Boiler House | B8: 42.731225 | C8: -73.681762
A9: Russell Sage Laboratory | B9: 42.730864 | C9: -73.681602 | E9: Repository CSV
A10: Troy Building | B10: 42.731083 | C10: -73.680523 | E10: https://github.com/rgtdthrd/RPI-Atlas/blob/ad4c20d72a5a9116513332047e3ffc1b6d84443e/app/src/main/res/raw/landmarkdata.csv
A11: North hall | B11: 42.731361 | C11: -73.679828
A12: E Complex | B12: 42.731377 | C12: -73.67919 | E12: Reviewed 2026-09-29. The branch commit is dated 2024-12-11.
A13: Ricketts Building | B13: 42.730902 | C13: -73.679751
A14: 87 Gymnasium | B14: 42.730785 | C14: -73.678864 | E14: The commit date is not a campus inspection date.
A15: Quadrangle Complex | B15: 42.730132 | C15: -73.677723
A16: Low Center for Industrial Innovation | B16: 42.729403 | C16: -73.678687 | E16: Source labels do not establish current accessibility.
A17: RPI Playhouse | B17: 42.72921 | C17: -73.67816
A18: Darrin Communications Center | B18: 42.729471 | C18: -73.679255
A19: Jonsson Engineering Center | B19: 42.729602 | C19: -73.680188
A20: Jonsson-Rowland Science Center | B20: 42.72882 | C20: -73.680378
A21: Cogswell Laboratory | B21: 42.728182 | C21: -73.681251
A22: Materials Research Center | B22: 42.728313 | C22: -73.681969
A23: Voorhees Computing Center | B23: 42.729247 | C23: -73.681925
A24: Folsom Library | B24: 42.729347 | C24: -73.682548
A25: Greene Building | B25: 42.730018 | C25: -73.681169
A26: Lally Hall | B26: 42.730083 | C26: -73.6819
A27: Amos Eaton Hall | B27: 42.730212 | C27: -73.682566
A28: Black Cultural Center | B28: 42.732485 | C28: -73.682878
... A72: Winslow Building | B72: 42.730921 | C72: -73.684312

Sheet Nodes
A1: Name | B1: Latitude | C1: Longitude | E1: Original source
A2: N71 | B2: 42.730921 | C2: -73.684312 | E2: ATLAS Graph Data.xlsx / Nodes
A3: N72 | B3: 42.732426 | C3: -73.671606
A4: N73 | B4: 42.733058 | C4: -73.67654 | E4: All original records and values in A:C are preserved.
A5: N74 | B5: 42.730771 | C5: -73.677224
A6: N75 | B6: 42.730644 | C6: -73.676221 | E6: Repository comparison
A7: N76 | B7: 42.730943 | C7: -73.675648 | E7: All 377 names match in order. Coordinate differences are below 0.001 m.
A8: N77 | B8: 42.731909 | C8: -73.67463
A9: N78 | B9: 42.732714 | C9: -73.674311 | E9: Repository CSV
A10: N79 | B10: 42.730915 | C10: -73.673793 | E10: https://github.com/rgtdthrd/RPI-Atlas/blob/ad4c20d72a5a9116513332047e3ffc1b6d84443e/app/src/main/res/raw/nodedata.csv
A11: N80 | B11: 42.731346 | C11: -73.674296
A12: N81 | B12: 42.731265 | C12: -73.671908 | E12: Reviewed 2026-09-29. The branch commit is dated 2024-12-11.
A13: N82 | B13: 42.731127 | C13: -73.673038
A14: N83 | B14: 42.732507 | C14: -73.672672 | E14: The commit date is not a campus inspection date.
A15: N84 | B15: 42.731369 | C15: -73.675107
A16: N85 | B16: 42.730605 | C16: -73.674052 | E16: Source labels do not establish current accessibility.
A17: N86 | B17: 42.730429 | C17: -73.674587
A18: N87 | B18: 42.730334 | C18: -73.674703
A19: N88 | B19: 42.730086 | C19: -73.675036
A20: N89 | B20: 42.730308 | C20: -73.675862
A21: N90 | B21: 42.730713 | C21: -73.675266
A22: N91 | B22: 42.731667 | C22: -73.672214
A23: N92 | B23: 42.731659 | C23: -73.671797
A24: N93 | B24: 42.73169 | C24: -73.673134
A25: N94 | B25: 42.731653 | C25: -73.672935
A26: N95 | B26: 42.729121 | C26: -73.672521
A27: N96 | B27: 42.729514 | C27: -73.674417
A28: N97 | B28: 42.729363 | C28: -73.673436
... A378: N448 | B378: 42.730489 | C378: -73.677718

Sheet Edges
A1: Node 1 Name | B1: Node 2 Name | C1: Is Accessible | E1: Original source
A2: N77 | B2: N78 | C2: TRUE | E2: ATLAS Graph Data.xlsx / Edges
A3: N73 | B3: N78 | C3: TRUE
A4: N74 | B4: N73 | C4: TRUE | E4: All original records and values in A:C are preserved.
A5: N74 | B5: N75 | C5: TRUE
A6: N76 | B6: N75 | C6: TRUE | E6: Repository comparison
A7: N77 | B7: N80 | C7: TRUE | E7: All 584 connections and flags match the repository CSV in order.
A8: N79 | B8: N80 | C8: TRUE
A9: N82 | B9: N79 | C9: TRUE | E9: Repository CSV
A10: N82 | B10: N81 | C10: TRUE | E10: https://github.com/rgtdthrd/RPI-Atlas/blob/ad4c20d72a5a9116513332047e3ffc1b6d84443e/app/src/main/res/raw/edgedata.csv
A11: N72 | B11: N83 | C11: TRUE
A12: N78 | B12: N83 | C12: TRUE | E12: Reviewed 2026-09-29. The branch commit is dated 2024-12-11.
A13: N77 | B13: N84 | C13: TRUE
A14: N76 | B14: N84 | C14: TRUE | E14: The commit date is not a campus inspection date.
A15: N79 | B15: N85 | C15: TRUE
A16: N86 | B16: N85 | C16: TRUE | E16: Source labels do not establish current accessibility.
A17: N87 | B17: N86 | C17: TRUE
A18: N75 | B18: N89 | C18: TRUE
A19: N88 | B19: N89 | C19: TRUE
A20: N87 | B20: N88 | C20: TRUE
A21: N76 | B21: N90 | C21: TRUE
A22: Admissions Office | B22: N90 | C22: TRUE
A23: N87 | B23: N90 | C23: TRUE
A24: Chapel and Cultural Center | B24: N91 | C24: TRUE
A25: N92 | B25: N91 | C25: TRUE
A26: N82 | B26: N94 | C26: TRUE
A27: N93 | B27: N94 | C27: TRUE
A28: N83 | B28: N94 | C28: TRUE
... A585: N128 | B585: N448 | C585: TRUE
